<?xml version="1.0" ?>
<sdf version="1.5">
  <model name="pioneer2dx" canonical_link='base_footprint'>
    <plugin
        filename="ignition-gazebo-joint-state-publisher-system"
        name="ignition::gazebo::systems::JointStatePublisher">
    </plugin>

    <link name='base_footprint'/>

    <joint name='footprint_to_base_joint' type='fixed'>
      <pose>0 0 0.01 0 0 0</pose>
      <parent>base_footprint</parent>
      <child>base_link</child>
      <use_parent_model_frame>true</use_parent_model_frame>
    </joint>

    <link name="base_link">
      <pose relative_to='base_footprint'>0 0 0.16 0 0 0</pose>
      <inertial>
        <mass>5.67</mass>
        <inertia>
          <ixx>0.07</ixx>
          <iyy>0.08</iyy>
          <izz>0.10</izz>
          <ixy>0</ixy>
          <ixz>0</ixz>
          <iyz>0</iyz>
        </inertia>
      </inertial>
      <collision name="collision">
        <geometry>
          <box>
            <size>0.445 0.277 0.17</size>
          </box>
        </geometry>
      </collision>
      <visual name="visual">
        <pose>0 0 0.04 0 0 0</pose>
        <geometry>
          <mesh>
            <uri>model://pioneer2dx/meshes/chassis.dae</uri>
          </mesh>
        </geometry>
      </visual>
      <collision name="caster_collision">
        <pose>-0.200 0 -0.12 0 0 0</pose>
        <geometry>
          <sphere>
            <radius>0.04</radius>
          </sphere>
        </geometry>
        <surface>
          <friction>
            <ode>
              <mu>0</mu>
              <mu2>0</mu2>
              <slip1>1.0</slip1>
              <slip2>1.0</slip2>
            </ode>
          </friction>
        </surface>
      </collision>
      <visual name="caster_visual">
        <pose>-0.200 0 -0.12 0 0 0</pose>
        <geometry>
          <sphere>
            <radius>0.04</radius>
          </sphere>
        </geometry>
        <material>
          <script>
            <uri>file://media/materials/scripts/gazebo.material</uri>
            <name>Gazebo/FlatBlack</name>
          </script>
        </material>
      </visual>

      <!-- IMU Sensor -->
      <sensor name="imu_sensor" type="imu">
        <always_on>true</always_on>
        <update_rate>200</update_rate>
        <topic>/imu/data</topic>
        <ignition_frame_id>base_link</ignition_frame_id>
        <imu>
          <angular_velocity>
            <x><noise type="gaussian"><mean>0</mean><stddev>0.009</stddev></noise></x>
            <y><noise type="gaussian"><mean>0</mean><stddev>0.009</stddev></noise></y>
            <z><noise type="gaussian"><mean>0</mean><stddev>0.009</stddev></noise></z>
          </angular_velocity>
          <linear_acceleration>
            <x><noise type="gaussian"><mean>0</mean><stddev>0.001</stddev></noise></x>
            <y><noise type="gaussian"><mean>0</mean><stddev>0.001</stddev></noise></y>
            <z><noise type="gaussian"><mean>0</mean><stddev>0.001</stddev></noise></z>
          </linear_acceleration>
        </imu>
      </sensor>
    </link>

    <link name="lidar_link">
      <pose relative_to='base_link'>0 0 0.19 0 0 0</pose>
      <inertial>
        <mass>0.1</mass>
        <inertia>
          <ixx>0.000166667</ixx>
          <iyy>0.000166667</iyy>
          <izz>0.000166667</izz>
        </inertia>
      </inertial>
      <collision name="collision">
        <geometry>
          <box>
            <size>0.1 0.1 0.1</size>
          </box>
        </geometry>
      </collision>
      <visual name="visual">
        <geometry>
          <box>
            <size>0.1 0.1 0.1</size>
          </box>
        </geometry>
      </visual>

      <sensor name='front_lidar' type='gpu_lidar'>
        <pose>0 0 0 0 0 0</pose>
        <topic>/scan</topic>
        <ignition_frame_id>lidar_link</ignition_frame_id>
        <update_rate>20</update_rate>
        <lidar>
          <scan>
            <horizontal>
              <samples>1800</samples> <!-- 1800 rays for 0.2 deg resolution -->
              <resolution>1</resolution>
              <min_angle>-3.1459</min_angle>
              <max_angle>3.1459</max_angle>
            </horizontal>
            <vertical>
              <samples>16</samples>
              <resolution>1</resolution>
              <min_angle>-0.261799</min_angle>
              <max_angle>0.261799</max_angle>
            </vertical>
          </scan>
          <range>
            <min>0.05</min>
            <max>100</max>
            <resolution>0.01</resolution>
          </range>
          <noise>
            <type>gaussian</type>
            <mean>0</mean>
            <stddev>0.01</stddev>
          </noise>
        </lidar>
        <visualize>true</visualize>
      </sensor>
    </link>

    <link name="right_wheel">
      <pose relative_to='base_link'>0.1 -0.17 -0.05 1.5707 0 0</pose>
      <inertial>
        <mass>1.5</mass>
        <inertia>
          <ixx>0.0051</ixx>
          <iyy>0.0051</iyy>
          <izz>0.0090</izz>
          <ixy>0</ixy>
          <ixz>0</ixz>
          <iyz>0</iyz>
        </inertia>
      </inertial>
      <collision name="collision">
        <geometry>
          <cylinder>
            <radius>0.11</radius>
            <length>0.05</length>
          </cylinder>
        </geometry>
        <surface>
          <friction>
            <ode>
              <mu>100000.0</mu>
              <mu2>100000.0</mu2>
              <slip1>0.0</slip1>
              <slip2>0.0</slip2>
            </ode>
          </friction>
        </surface>
      </collision>
      <visual name="visual">
        <geometry>
          <cylinder>
            <radius>0.11</radius>
            <length>0.05</length>
          </cylinder>
        </geometry>
        <material>
          <script>
            <uri>file://media/materials/scripts/gazebo.material</uri>
            <name>Gazebo/FlatBlack</name>
          </script>
        </material>
      </visual>
    </link>
    <link name="left_wheel">
      <pose relative_to='base_link'>0.1 0.17 -0.05 -1.5707 0 0</pose>
      <inertial>
        <mass>1.5</mass>
        <inertia>
          <ixx>0.0051</ixx>
          <iyy>0.0051</iyy>
          <izz>0.0090</izz>
          <ixy>0</ixy>
          <ixz>0</ixz>
          <iyz>0</iyz>
        </inertia>
      </inertial>
      <collision name="collision">
        <geometry>
          <cylinder>
            <radius>0.11</radius>
            <length>0.05</length>
          </cylinder>
        </geometry>
        <surface>
          <friction>
            <ode>
              <mu>100000.0</mu>
              <mu2>100000.0</mu2>
              <slip1>0.0</slip1>
              <slip2>0.0</slip2>
            </ode>
          </friction>
        </surface>
      </collision>
      <visual name="visual">
        <geometry>
          <cylinder>
            <radius>0.11</radius>
            <length>0.05</length>
          </cylinder>
        </geometry>
        <material>
          <script>
            <uri>file://media/materials/scripts/gazebo.material</uri>
            <name>Gazebo/FlatBlack</name>
          </script>
        </material>
      </visual>
    </link>

    <joint name='lidar_joint' type='fixed'>
      <parent>base_link</parent>
      <child>lidar_link</child>
    </joint>

    <!-- D435 Camera Link -->
    <link name="camera_link">
      <pose relative_to='base_link'>0.25 0 0.10 0 0 0</pose>
      <inertial>
        <mass>0.072</mass>
        <inertia>
          <ixx>0.00003881</ixx>
          <iyy>0.00000498</iyy>
          <izz>0.00003879</izz>
        </inertia>
      </inertial>
      <collision name="collision">
        <geometry>
          <box>
            <size>0.025 0.09 0.025</size>
          </box>
        </geometry>
      </collision>
      <visual name="visual">
        <geometry>
          <box>
            <size>0.025 0.09 0.025</size>
          </box>
        </geometry>
        <material>
          <ambient>0.1 0.1 0.1 1</ambient>
          <diffuse>0.2 0.2 0.2 1</diffuse>
        </material>
      </visual>

      <!-- RGB Camera -->
      <sensor name="color_camera" type="camera">
        <pose>0 0 0 0 0 0</pose>
        <topic>/camera/color/image_raw</topic>
        <camera_info_topic>/camera/color/camera_info</camera_info_topic>
        <ignition_frame_id>camera_color_optical_frame</ignition_frame_id>
        <update_rate>30</update_rate>
        <always_on>true</always_on>
        <visualize>true</visualize>
        <camera>
          <horizontal_fov>1.211</horizontal_fov>
          <image>
            <width>640</width>
            <height>480</height>
            <format>RGB_INT8</format>
          </image>
          <clip>
            <near>0.1</near>
            <far>100</far>
          </clip>
        </camera>
      </sensor>

      <!-- Depth Camera -->
      <sensor name="depth_camera" type="depth_camera">
        <pose>0 0 0 0 0 0</pose>
        <topic>/camera/depth/image_raw</topic>
        <camera_info_topic>/camera/depth/camera_info</camera_info_topic>
        <ignition_frame_id>camera_color_optical_frame</ignition_frame_id>
        <update_rate>30</update_rate>
        <always_on>true</always_on>
        <visualize>true</visualize>
        <camera>
          <horizontal_fov>1.211</horizontal_fov>
          <image>
            <width>640</width>
            <height>480</height>
            <format>R_FLOAT32</format>
          </image>
          <clip>
            <near>0.1</near>
            <far>100</far>
          </clip>
        </camera>
      </sensor>

      <!-- RGBD Camera for Point Cloud -->
      <sensor name="rgbd_camera" type="rgbd_camera">
        <pose>0 0 0 0 0 0</pose>
        <topic>/camera</topic>
        <ignition_frame_id>camera_link</ignition_frame_id>
        <update_rate>15</update_rate>
        <always_on>true</always_on>
        <visualize>true</visualize>
        <camera>
          <horizontal_fov>1.211</horizontal_fov>
          <image>
            <width>640</width>
            <height>480</height>
          </image>
          <clip>
            <near>0.1</near>
            <far>100</far>
          </clip>
        </camera>
      </sensor>
    </link>

    <joint name='camera_joint' type='fixed'>
      <parent>base_link</parent>
      <child>camera_link</child>
    </joint>

    <joint name='left_wheel_joint' type='revolute'>
      <pose relative_to='left_wheel'/>
      <parent>base_link</parent>
      <child>left_wheel</child>
      <use_parent_model_frame>true</use_parent_model_frame>
      <axis>
        <xyz expressed_in='__model__'>0 1 0</xyz>
        <limit>
          <lower>-1.79769e+308</lower>
          <upper>1.79769e+308</upper>
          <effort>10</effort>
          <velocity>10</velocity>
        </limit>
      </axis>
    </joint>

    <joint name='right_wheel_joint' type='revolute'>
      <pose relative_to='right_wheel'/>
      <parent>base_link</parent>
      <child>right_wheel</child>
      <use_parent_model_frame>true</use_parent_model_frame>
      <axis>
        <xyz expressed_in='__model__'>0 1 0</xyz>
        <limit>
          <lower>-1.79769e+308</lower>
          <upper>1.79769e+308</upper>
          <effort>10</effort>
          <velocity>10</velocity>
        </limit>
      </axis>
    </joint>

    <plugin filename="ignition-gazebo-diff-drive-system" name="ignition::gazebo::systems::DiffDrive">
      <topic>/cmd_vel</topic>
      <left_joint>left_wheel_joint</left_joint>
      <right_joint>right_wheel_joint</right_joint>
      <wheel_separation>0.34</wheel_separation>
      <wheel_radius>0.11</wheel_radius>
      <max_linear_acceleration>1.5</max_linear_acceleration>
      <min_linear_acceleration>-1.5</min_linear_acceleration>
      <max_angular_acceleration>1.6</max_angular_acceleration>
      <min_angular_acceleration>-1.6</min_angular_acceleration>
      <max_linear_velocity>0.4</max_linear_velocity>
      <min_linear_velocity>-0.4</min_linear_velocity>
      <max_angular_velocity>1</max_angular_velocity>
      <min_angular_velocity>-1</min_angular_velocity>
    </plugin>

    <!-- Moving Forward-->
    <plugin filename="libignition-gazebo-triggered-publisher-system.so" name="ignition::gazebo::systems::TriggeredPublisher">
      <input type="ignition.msgs.Int32" topic="/keyboard/keypress">
        <match field="data">16777235</match>
      </input>
      <output type="ignition.msgs.Twist" topic="/cmd_vel">
        linear: {x: 0.4}, angular: {z: 0.0}
      </output>
    </plugin>

    <!-- Moving Backward-->
    <plugin filename="libignition-gazebo-triggered-publisher-system.so" name="ignition::gazebo::systems::TriggeredPublisher">
      <input type="ignition.msgs.Int32" topic="/keyboard/keypress">
        <match field="data">16777237</match>
      </input>
      <output type="ignition.msgs.Twist" topic="/cmd_vel">
        linear: {x: -0.4}, angular: {z: 0.0}
      </output>
    </plugin>

    <!-- Moving Left-->
    <plugin filename="libignition-gazebo-triggered-publisher-system.so" name="ignition::gazebo::systems::TriggeredPublisher">
      <input type="ignition.msgs.Int32" topic="/keyboard/keypress">
        <match field="data">16777234</match>
      </input>
      <output type="ignition.msgs.Twist" topic="/cmd_vel">
        linear: {x: 0.0}, angular: {z: 1}
      </output>
    </plugin>

    <!-- Moving Right-->
    <plugin filename="libignition-gazebo-triggered-publisher-system.so" name="ignition::gazebo::systems::TriggeredPublisher">
      <input type="ignition.msgs.Int32" topic="/keyboard/keypress">
        <match field="data">16777236</match>
      </input>
      <output type="ignition.msgs.Twist" topic="/cmd_vel">
        linear: {x: 0.0}, angular: {z: -1}
      </output>
    </plugin>

    <!-- Stop Moving-->
    <plugin filename="libignition-gazebo-triggered-publisher-system.so" name="ignition::gazebo::systems::TriggeredPublisher">
      <input type="ignition.msgs.Int32" topic="/keyboard/keypress">
        <match field="data">83</match>        <!--83 is the key s-->
      </input>
      <output type="ignition.msgs.Twist" topic="/cmd_vel">
        linear: {x: 0.0}, angular: {z: 0.0}
      </output>
    </plugin>
  </model>
</sdf>
